Workbook

Sheet Presupuesto de Obras
A1: PRESUPUESTO DE OBRAS MENORES - CONTROL Y AJUSTE DE PARTIDAS
A2: Cliente: María Luz Camus Romo | E2: Meta Presupuesto: | F2: 9180000
A3: Dirección: Miguel Claro 1691 D - Providencia | E3: Total Actual: | F3: =G87 -> 9180000
A4: Cotización: PTO-2026-078 | Fecha: 2026-09-21 | Plazo: 50 días corridos | E4: Diferencia p/ Meta: | F4: =F3-F2 -> 0
E5: =IF(F4=0,"✅ ¡PRESUPUESTO CUADRADO EXACTO EN $9.180.000!",IF(F4>0,"⚠️ SOBRAN " & TEXT(F4,"$#,##0") & " (DEBES BAJAR VALORES)","⚠️ FALTAN " & TEXT(-F4,"$#,##0") & " (DEBES SUBIR VALORES)")) -> ✅ ¡PRESUPUESTO CUADRADO EXACTO EN $9.180.000!
A6: 💡 INSTRUCCIÓN PARA EL MAESTRO / CONSTRUCTOR: Modifica las celdas en amarillo (Cantidad y Precio Unitario). Las fórmulas calcularán subtotales y el panel superior te dirá cuánto te falta o te sobra para los $9.180.000.
A8: # | B8: Partida / Trabajo | C8: Especificación y Detalle | D8: Unidad | E8: Cantidad | F8: Precio Unitario ($) | G8: Subtotal Partida ($)
A9: 1. RECINTO: GENERAL (Medidas: 3m × 3m × 2.4m)
A10: 1.1 | B10: Empastado y Reparación base de muros y fisuras de la casa | C10: Preparación y reparación de fisuras y enlucido base en muros de la vivienda | D10: gl | E10: 1 | F10: 340000 | G10: =E10*F10 -> 340000
A11: 1.2 | B11: Reparación de filtración en escala y pintura | C11: Sellado, reparación de estuco/yeso y acabado de pintura | D11: gl | E11: 1 | F11: 272000 | G11: =E11*F11 -> 272000
A12: 1.3 | B12: Reparación de 6 puertas interiores | C12: Ajuste de bisagras, cerraduras, rebaje y cuadratura | D12: gl | E12: 1 | F12: 108800 | G12: =E12*F12 -> 108800
A13: 1.4 | B13: Pintura exterior (2 pisos), reparación de alero exterior y tratamiento de humedad en muros bajos | C13: Limpieza y pintura exterior de fachada (2 pisos), reparación estructural y sellado de alero exterior, y tratamiento antihumedad con picado, puente adherente e impermeabilización de muros bajos | D13: gl | E13: 1 | F13: 544000 | G13: =E13*F13 -> 544000
A14: 1.5 | B14: Reparación de patio, retiro de escombros y aseo general | C14: Despeje, limpieza fina, acopio y retiro autorizado de escombros | D14: gl | E14: 1 | F14: 136000 | G14: =E14*F14 -> 136000
A15: SUBTOTAL GENERAL: | G15: =SUM(G10:G14)
A17: 2. RECINTO: LIVING / COMEDOR (Medidas: 7m × 3m × 2.4m)
A18: 2.1 | B18: Reparación de Ventanal (vidrios 20x30 cm) | C18: Mano de obra, suministro de vidrios 20x30, sellado con silicona y junquillos | D18: gl | E18: 1 | F18: 299200 | G18: =E18*F18 -> 299200
A19: 2.2 | B19: Retiro de Parquet existente (21 m²) | C19: Desmonte cuidadoso de entablado de parquet, despeje y acopio de material | D19: gl | E19: 1 | F19: 204000 | G19: =E19*F19 -> 204000
A20: 2.3 | B20: Instalación de Cerámica de Piso (21 m²) | C20: Incluye adhesivo cerámico bekron, fragüe, nivelación y colocación | D20: gl | E20: 1 | F20: 652800 | G20: =E20*F20 -> 652800
A21: 2.4 | B21: Picado de piso para tuberías y canalización eléctrica | C21: Ranurado y apertura de trazado para embutir canalizaciones eléctricas subterráneas | D21: gl | E21: 1 | F21: 149600 | G21: =E21*F21 -> 149600
A22: 2.5 | B22: Puntos eléctricos (6 enchufes + 4 centros de luz), canalización y cableado de materiales | C22: Incluye suministro de módulos certificados SEC, canalizaciones, cableado normalizado, cajas de derivación y tapas | D22: gl | E22: 1 | F22: 285600 | G22: =E22*F22 -> 285600
A23: 2.6 | B23: Pintura y empastado completo de muros (Pintura incluida) | C23: Empastado, lijado prolijo y aplicación de 2 manos de pintura esmalte al agua en muros de living y comedor | D23: gl | E23: 1 | F23: 380800 | G23: =E23*F23 -> 380800
A24: SUBTOTAL LIVING / COMEDOR: | G24: =SUM(G18:G23)
A26: 3. RECINTO: PASILLO (Medidas: 2m × 1m × 2.4m)
A27: 3.1 | B27: Retiro de Parquet existente | C27: Desmonte y limpieza de base | D27: gl | E27: 1 | F27: 81600 | G27: =E27*F27 -> 81600
A28: 3.2 | B28: Instalación de Cerámica con materiales incluidos | C28: Nivelación, adhesivo, fraguado y cerámica para pasillo | D28: gl | E28: 1 | F28: 190400 | G28: =E28*F28 -> 190400
A29: 3.3 | B29: Puntos eléctricos (2 enchufes + 2 centros de luz + 1 interruptor), canalización y cableado de materiales | C29: Incluye suministro de módulos certificados SEC, canalizaciones, cableado normalizado, cajas de derivación y tapas | D29: gl | E29: 1 | F29: 217600 | G29: =E29*F29 -> 217600
A30: 3.4 | B30: Pintura y empastado de muros y cielos (Pintura incluida) | C30: Preparación de muros, empaste y aplicación de 2 manos de esmalte al agua en pasillo | D30: gl | E30: 1 | F30: 108800 | G30: =E30*F30 -> 108800
A31: SUBTOTAL PASILLO: | G31: =SUM(G27:G30)
A33: 4. RECINTO: COCINA (Medidas: 2m × 1.5m × 2.4m)
A34: 4.1 | B34: Suministro e Instalación de Puerta Nueva | C34: Montaje de hoja, colocación de marco/bisagras y cerradura | D34: un | E34: 1 | F34: 190400 | G34: =E34*F34 -> 190400
A35: 4.2 | B35: Instalación de Cerámica en Muros de Cocina | C35: Revestimiento cerámico de salpicaderos/muros, adhesivo y fragüe | D35: gl | E35: 1 | F35: 231200 | G35: =E35*F35 -> 231200
A36: 4.3 | B36: Puntos eléctricos (2 enchufes + módulo encendido + 1 centro luz), canalización y cableado de materiales | C36: Incluye suministro de módulos certificados SEC, canalizaciones, cableado normalizado, cajas de derivación y tapas | D36: gl | E36: 1 | F36: 231200 | G36: =E36*F36 -> 231200
A37: 4.4 | B37: Pintura esmalte al agua en cielos y muros (Pintura incluida) | C37: Preparación de superficies, tratamiento antihumedad y pintura esmalte al agua en cielos y muros de cocina | D37: gl | E37: 1 | F37: 95200 | G37: =E37*F37 -> 95200
A38: SUBTOTAL COCINA: | G38: =SUM(G34:G37)
A40: 5. RECINTO: BAÑO PRIMER PISO (Medidas: 2m × 3m × 2.4m)
A41: 5.1 | B41: Instalación de Piso Vinílico | C41: Preparación de base y colocación de piso vinílico resistente a humedad | D41: gl | E41: 1 | F41: 149600 | G41: =E41*F41 -> 149600
A42: 5.2 | B42: Construcción e Instalación de Cerámica en Receptáculo de ducha | C42: Impermeabilización previa, pendiente hacia desagüe y revestimiento cerámico | D42: gl | E42: 1 | F42: 204000 | G42: =E42*F42 -> 204000
A43: 5.3 | B43: Cambio y Montaje de WC con fittings | C43: Desmonte de artefacto antiguo, sello de cera, pernos de anclaje y conexión flexible | D43: un | E43: 1 | F43: 122400 | G43: =E43*F43 -> 122400
A44: 5.4 | B44: Pintura Esmalte al Agua en Muros (2 Manos antihumedad) | C44: Preparación de muros, sellador y esmalte al agua fungicida para baño | D44: gl | E44: 1 | F44: 122400 | G44: =E44*F44 -> 122400
A45: 5.5 | B45: Electricidad de baño (1 enchufe + 1 interruptor + canalizado) | C45: Puntos eléctricos con protección de humedad y conexión a tierra | D45: gl | E45: 1 | F45: 108800 | G45: =E45*F45 -> 108800
...

Sheet Resumen Ejecutivo
A1: RESUMEN EJECUTIVO POR RECINTO - DISTRIBUCIÓN DEL VALOR TOTAL
A3: # | B3: Recinto / Espacio | C3: Subtotal Asignado ($) | D3: % Presupuesto | E3: Descripción de Cobertura
A4: 1 | B4: GENERAL | C4: ='Presupuesto de Obras'!G15 | D4: =C4/'Presupuesto de Obras'!G87 | E4: Muros base, escala, puertas, exterior unificado y aseo
A5: 2 | B5: Living / Comedor | C5: ='Presupuesto de Obras'!G24 | D5: =C5/'Presupuesto de Obras'!G87 | E5: Ventanal, parquet, cerámica, electricidad y pintura
A6: 3 | B6: Pasillo | C6: ='Presupuesto de Obras'!G31 | D6: =C6/'Presupuesto de Obras'!G87 | E6: Parquet, cerámica, electricidad y pintura
A7: 4 | B7: Cocina | C7: ='Presupuesto de Obras'!G38 | D7: =C7/'Presupuesto de Obras'!G87 | E7: Puerta, cerámica muros, electricidad y pintura cielos
A8: 5 | B8: Baño Primer Piso | C8: ='Presupuesto de Obras'!G46 | D8: =C8/'Presupuesto de Obras'!G87 | E8: Partidas de obra menor acordadas
A9: 6 | B9: Dormitorio Primer Piso | C9: ='Presupuesto de Obras'!G52 | D9: =C9/'Presupuesto de Obras'!G87 | E9: Piso vinílico, electricidad y pintura
A10: 7 | B10: Segundo piso Dormitorio 1 | C10: ='Presupuesto de Obras'!G58 | D10: =C10/'Presupuesto de Obras'!G87 | E10: Pintura, pulido/vitrificado parquet y electricidad picada
A11: 8 | B11: Segundo piso Dormitorio 2 | C11: ='Presupuesto de Obras'!G64 | D11: =C11/'Presupuesto de Obras'!G87 | E11: Pintura, pulido/vitrificado parquet y electricidad picada
A12: 9 | B12: Segundo piso Dormitorio 3 | C12: ='Presupuesto de Obras'!G70 | D12: =C12/'Presupuesto de Obras'!G87 | E12: Pintura, pulido/vitrificado parquet y electricidad picada
A13: 10 | B13: Baño Segundo piso | C13: ='Presupuesto de Obras'!G78 | D13: =C13/'Presupuesto de Obras'!G87 | E13: Gasfitería PPR, retiro tina, receptáculo, cielo y cerámica
A14: 11 | B14: Logia | C14: ='Presupuesto de Obras'!G85 | D14: =C14/'Presupuesto de Obras'!G87 | E14: Radier, cerámica piso, gasfitería y electricidad
B15: TOTAL GLOBAL: | C15: =SUM(C4:C14) | D15: =SUM(D4:D14)
